Workbook

Sheet README
A1: THE UNLOX ACADEMY - DA/DS TRACK
A2: Excel Minor Project - Sales Operations Analytics
A3: Interview-Grade Data Analytics Assessment · 100 Marks
A5: THE SCENARIO
A6: You have just joined the analytics team at a fast-growing multi-category retailer operating across 6 Indian cities.
A7: The head of sales has handed you 5 raw data files - Orders, Customers, Products, Sales Reps, and Targets - and asked
A8: you to answer a set of business questions before the leadership review tomorrow morning.
A10: The data is REAL-WORLD messy: duplicates, missing references, inconsistent case, invalid records, discontinued SKUs.
A11: Part of the assessment is spotting and handling these issues correctly. A wrong-looking answer isn't always wrong -
A12: sometimes the data itself is telling a story.
A14: RULES OF THE ASSESSMENT
A15: 1. Write your answer in the YELLOW cells on each question sheet. Empty answer cell = 0 marks.
... A22: MARKS DISTRIBUTION
A23: Section | B23: Topic | C23: Questions | D23: Marks
A24: Q1 | B24: Lookup Functions (VLOOKUP, INDEX-MATCH, chained lookups) | C24: 8 | D24: 25
A25: Q2 | B25: Data Cleaning & Quality Diagnostics | C25: 6 | D25: 20
A26: Q3 | B26: Conditional Aggregation (SUMIFS, COUNTIFS, IF logic) | C26: 6 | D26: 25
A27: Q4 | B27: Pivot Tables (2D pivots, % of total, calculated fields) | C27: 5 | D27: 20
A28: Q5 | B28: Advanced (Ranking, Running Totals, Multi-condition) | C28: 5 | D28: 10
B29: TOTAL | C29: 30 | D29: 100
A32: PERFORMANCE TIERS
A33: Marks | B33: Tier | C33: Interview Verdict
A34: 85 - 100 | B34: Excellent | C34: Round 1 clear - Excel not a concern
A35: 70 - 84 | B35: Good | C35: Round 1 clear with minor gaps
A36: 55 - 69 | B36: Borderline | C36: Round 1 uncertain - needs revision
A37: 40 - 54 | B37: Weak | C37: Round 1 likely reject - 2 weeks of practice needed
A38: < 40 | B38: Insufficient | C38: Round 1 reject - foundational gaps
A41: DATA SHEETS OVERVIEW
A42: Sheet | B42: Rows | C42: Key Columns | D42: Joins to
A43: Orders | B43: ~2000 | C43: order_id, order_date, customer_id, product_id, sales_rep_id, quantity, unit_price, discount_pct, final_amount, payment_status, ship_city | D43: All others
A44: Customers | B44: 300 | C44: customer_id (PK), customer_name, age, city, segment, signup_date | D44: Orders via customer_id
A45: Products | B45: 60 | C45: product_id (PK), product_name, category, unit_cost, unit_price, is_active | D45: Orders via product_id
A46: Sales_Reps | B46: 30 | C46: rep_id (PK), rep_name, region, hire_date, team_lead_id | D46: Orders via sales_rep_id, self-join via team_lead_id
A47: Targets | B47: 30 × 12 | C47: rep_id (PK), Jan-24 through Dec-24 monthly target values | D47: Sales_Reps via rep_id

Sheet Orders
A1: order_id | B1: order_date | C1: customer_id | D1: product_id | E1: sales_rep_id | F1: quantity | G1: unit_price | H1: discount_pct | I1: final_amount | J1: payment_status | K1: ship_city | L1: Column1 | M1: #DIV/0! | N1: category | O1: segment | P1: age | Q1: region | R1: unit_cost | S1: month
A2: ORD-00001 | B2: 45549 | C2: CUST-0243 | D2: PROD-014 | E2: R007 | F2: 8 | G2: 3620 | H2: 15.4 | I2: 24500.16 | J2: Completed | K2: Pune | M2: =IFERROR(INDEX(Products!$C$2:$C$61,MATCH(D2,Products!$A$2:$A$61,0)),"NA") -> Apparel | N2: =IFERROR(INDEX(Products!$C$2:$C$61,MATCH(D2,Products!$A$2:$A$61,0)),"NA") -> Apparel | O2: =IFERROR(INDEX(Customers!$E$2:$E$301,MATCH(C2,Customers!$A$2:$A$301,0)),"NA") -> SMB | P2: =IFERROR(INDEX(Customers!$C$2:$C$301,MATCH(C2,Customers!$A$2:$A$301,0)),"NA") -> 44 | Q2: =IFERROR(INDEX(Sales_Reps!$C$2:$C$31,MATCH(E2,Sales_Reps!$A$2:$A$31,0)),"NA") -> North | R2: =IFERROR(INDEX(Products!$D$2:$D$61,MATCH(D2,Products!$A$2:$A$61,0)),"") -> 2509 | S2: =DATE(YEAR(B2),MONTH(B2),1) -> 45536
A3: ORD-00002 | B3: 45340 | C3: CUST-0202 | D3: PROD-020 | E3: R005 | F3: 2 | G3: 820 | H3: 10.8 | I3: 1462.88 | J3: Pending | K3: Chennai | M3: =IFERROR(INDEX(Products!$C$2:$C$61,MATCH(D3,Products!$A$2:$A$61,0)),"NA") -> Apparel | N3: =IFERROR(INDEX(Products!$C$2:$C$61,MATCH(D3,Products!$A$2:$A$61,0)),"NA") -> Apparel | O3: =IFERROR(INDEX(Customers!$E$2:$E$301,MATCH(C3,Customers!$A$2:$A$301,0)),"NA") -> Retail | P3: =IFERROR(INDEX(Customers!$C$2:$C$301,MATCH(C3,Customers!$A$2:$A$301,0)),"NA") -> 39 | Q3: =IFERROR(INDEX(Sales_Reps!$C$2:$C$31,MATCH(E3,Sales_Reps!$A$2:$A$31,0)),"NA") -> North | R3: =IFERROR(INDEX(Products!$D$2:$D$61,MATCH(D3,Products!$A$2:$A$61,0)),"") -> 391 | S3: =DATE(YEAR(B3),MONTH(B3),1) -> 45323
A4: ORD-00003 | B4: 45371 | C4: CUST-0098 | D4: PROD-053 | E4: R014 | F4: 8 | G4: 470 | H4: 3.3 | I4: 3635.92 | J4: Pending | K4: Delhi | M4: =IFERROR(INDEX(Products!$C$2:$C$61,MATCH(D4,Products!$A$2:$A$61,0)),"NA") -> Sports | N4: =IFERROR(INDEX(Products!$C$2:$C$61,MATCH(D4,Products!$A$2:$A$61,0)),"NA") -> Sports | O4: =IFERROR(INDEX(Customers!$E$2:$E$301,MATCH(C4,Customers!$A$2:$A$301,0)),"NA") -> Retail | P4: =IFERROR(INDEX(Customers!$C$2:$C$301,MATCH(C4,Customers!$A$2:$A$301,0)),"NA") -> 52 | Q4: =IFERROR(INDEX(Sales_Reps!$C$2:$C$31,MATCH(E4,Sales_Reps!$A$2:$A$31,0)),"NA") -> South | R4: =IFERROR(INDEX(Products!$D$2:$D$61,MATCH(D4,Products!$A$2:$A$61,0)),"") -> 302 | S4: =DATE(YEAR(B4),MONTH(B4),1) -> 45352
A5: ORD-00004 | B5: 45413 | C5: CUST-0071 | D5: PROD-028 | E5: R006 | F5: 1 | G5: 3660 | H5: 15.7 | I5: 3085.38 | J5: Completed | K5: Delhi | M5: =IFERROR(INDEX(Products!$C$2:$C$61,MATCH(D5,Products!$A$2:$A$61,0)),"NA") -> Grocery | N5: =IFERROR(INDEX(Products!$C$2:$C$61,MATCH(D5,Products!$A$2:$A$61,0)),"NA") -> Grocery | O5: =IFERROR(INDEX(Customers!$E$2:$E$301,MATCH(C5,Customers!$A$2:$A$301,0)),"NA") -> Corporate | P5: =IFERROR(INDEX(Customers!$C$2:$C$301,MATCH(C5,Customers!$A$2:$A$301,0)),"NA") -> 46 | Q5: =IFERROR(INDEX(Sales_Reps!$C$2:$C$31,MATCH(E5,Sales_Reps!$A$2:$A$31,0)),"NA") -> North | R5: =IFERROR(INDEX(Products!$D$2:$D$61,MATCH(D5,Products!$A$2:$A$61,0)),"") -> 2214 | S5: =DATE(YEAR(B5),MONTH(B5),1) -> 45413
A6: ORD-00005 | B6: 45611 | C6: CUST-0180 | D6: PROD-012 | E6: R008 | F6: 1 | G6: 3160 | H6: 26 | I6: 2338.4 | J6: Completed | K6: Chennai | M6: =IFERROR(INDEX(Products!$C$2:$C$61,MATCH(D6,Products!$A$2:$A$61,0)),"NA") -> Apparel | N6: =IFERROR(INDEX(Products!$C$2:$C$61,MATCH(D6,Products!$A$2:$A$61,0)),"NA") -> Apparel | O6: =IFERROR(INDEX(Customers!$E$2:$E$301,MATCH(C6,Customers!$A$2:$A$301,0)),"NA") -> Retail | P6: =IFERROR(INDEX(Customers!$C$2:$C$301,MATCH(C6,Customers!$A$2:$A$301,0)),"NA") -> 36 | Q6: =IFERROR(INDEX(Sales_Reps!$C$2:$C$31,MATCH(E6,Sales_Reps!$A$2:$A$31,0)),"NA") -> North | R6: =IFERROR(INDEX(Products!$D$2:$D$61,MATCH(D6,Products!$A$2:$A$61,0)),"") -> 1886 | S6: =DATE(YEAR(B6),MONTH(B6),1) -> 45597
A7: ORD-00006 | B7: 45406 | C7: CUST-0275 | D7: PROD-032 | E7: R025 | F7: 4 | G7: 370 | H7: 29 | I7: 1050.8 | J7: Completed | K7: Mumbai | M7: =IFERROR(INDEX(Products!$C$2:$C$61,MATCH(D7,Products!$A$2:$A$61,0)),"NA") -> Home | N7: =IFERROR(INDEX(Products!$C$2:$C$61,MATCH(D7,Products!$A$2:$A$61,0)),"NA") -> Home | O7: =IFERROR(INDEX(Customers!$E$2:$E$301,MATCH(C7,Customers!$A$2:$A$301,0)),"NA") -> Retail | P7: =IFERROR(INDEX(Customers!$C$2:$C$301,MATCH(C7,Customers!$A$2:$A$301,0)),"NA") -> 36 | Q7: =IFERROR(INDEX(Sales_Reps!$C$2:$C$31,MATCH(E7,Sales_Reps!$A$2:$A$31,0)),"NA") -> West | R7: =IFERROR(INDEX(Products!$D$2:$D$61,MATCH(D7,Products!$A$2:$A$61,0)),"") -> 288 | S7: =DATE(YEAR(B7),MONTH(B7),1) -> 45383
A8: ORD-00007 | B8: 45455 | C8: CUST-0293 | D8: PROD-057 | E8: R024 | F8: 3 | G8: 960 | H8: 5.8 | I8: 2712.96 | J8: Completed | K8: Bengaluru | M8: =IFERROR(INDEX(Products!$C$2:$C$61,MATCH(D8,Products!$A$2:$A$61,0)),"NA") -> Sports | N8: =IFERROR(INDEX(Products!$C$2:$C$61,MATCH(D8,Products!$A$2:$A$61,0)),"NA") -> Sports | O8: =IFERROR(INDEX(Customers!$E$2:$E$301,MATCH(C8,Customers!$A$2:$A$301,0)),"NA") -> Retail | P8: =IFERROR(INDEX(Customers!$C$2:$C$301,MATCH(C8,Customers!$A$2:$A$301,0)),"NA") -> 27 | Q8: =IFERROR(INDEX(Sales_Reps!$C$2:$C$31,MATCH(E8,Sales_Reps!$A$2:$A$31,0)),"NA") -> West | R8: =IFERROR(INDEX(Products!$D$2:$D$61,MATCH(D8,Products!$A$2:$A$61,0)),"") -> 705 | S8: =DATE(YEAR(B8),MONTH(B8),1) -> 45444
A9: ORD-00008 | B9: 45617 | C9: CUST-0281 | D9: PROD-007 | E9: R019 | F9: 8 | G9: 1430 | H9: 2.4 | I9: 11165.44 | J9: Completed | K9: Bengaluru | M9: =IFERROR(INDEX(Products!$C$2:$C$61,MATCH(D9,Products!$A$2:$A$61,0)),"NA") -> Electronics | N9: =IFERROR(INDEX(Products!$C$2:$C$61,MATCH(D9,Products!$A$2:$A$61,0)),"NA") -> Electronics | O9: =IFERROR(INDEX(Customers!$E$2:$E$301,MATCH(C9,Customers!$A$2:$A$301,0)),"NA") -> Corporate | P9: =IFERROR(INDEX(Customers!$C$2:$C$301,MATCH(C9,Customers!$A$2:$A$301,0)),"NA") -> 57 | Q9: =IFERROR(INDEX(Sales_Reps!$C$2:$C$31,MATCH(E9,Sales_Reps!$A$2:$A$31,0)),"NA") -> East | R9: =IFERROR(INDEX(Products!$D$2:$D$61,MATCH(D9,Products!$A$2:$A$61,0)),"") -> 861 | S9: =DATE(YEAR(B9),MONTH(B9),1) -> 45597
A10: ORD-00009 | B10: 45549 | C10: CUST-0260 | D10: PROD-038 | E10: R008 | F10: 3 | G10: 5490 | H10: 14.2 | I10: 14131.26 | J10: Completed | K10: Bengaluru
A11: ORD-00010 | B11: 45396 | C11: CUST-0147 | D11: PROD-030 | E11: R028 | F11: 3 | G11: 970 | H11: 1.2 | I11: 2875.08 | J11: Completed | K11: Pune
A12: ORD-00011 | B12: 45560 | C12: CUST-0204 | D12: PROD-024 | E12: R010 | F12: 7 | G12: 2270 | H12: 7.1 | I12: 14761.81 | J12: Pending | K12: Hyderabad
A13: ORD-00012 | B13: 45332 | C13: CUST-0147 | D13: PROD-010 | E13: R024 | F13: 9 | G13: 2640 | H13: 21.7 | I13: 18604.08 | J13: Completed | K13: Pune
A14: ORD-00013 | B14: 45507 | C14: CUST-0280 | D14: PROD-002 | E14: R004 | F14: 3 | G14: 2600 | H14: 4.3 | I14: 7464.6 | J14: Cancelled | K14: Delhi
A15: ORD-00014 | B15: 45466 | C15: CUST-0008 | D15: PROD-036 | E15: R025 | F15: 3 | G15: 3250 | H15: 14.1 | I15: 8375.25 | J15: Refunded | K15: Pune
A16: ORD-00015 | B16: 45365 | C16: CUST-0052 | D16: PROD-060 | E16: R003 | F16: 1 | G16: 190 | H16: 20.7 | I16: 150.67 | J16: Completed | K16: Pune
A17: ORD-00016 | B17: 45546 | C17: CUST-0184 | D17: PROD-058 | E17: R014 | F17: 7 | G17: 2400 | H17: 10.2 | I17: 15086.4 | J17: Pending | K17: Pune
A18: ORD-00017 | B18: 45512 | C18: CUST-0056 | D18: PROD-028 | E18: R023 | F18: 4 | G18: 3660 | H18: 2.6 | I18: 14259.36 | J18: Completed | K18: Bengaluru
A19: ORD-00018 | B19: 45654 | C19: CUST-0273 | D19: PROD-047 | E19: R021 | F19: 8 | G19: 3450 | H19: 18.5 | I19: 22494 | J19: Completed | K19: Hyderabad
A20: ORD-00019 | B20: 45626 | C20: CUST-0182 | D20: PROD-051 | E20: R023 | F20: 5 | G20: 3450 | H20: 7.3 | I20: 15990.75 | J20: Completed | K20: Mumbai
A21: ORD-00020 | B21: 45394 | C21: CUST-0265 | D21: PROD-040 | E21: R023 | F21: 8 | G21: 1080 | H21: 2.2 | I21: 8449.92 | J21: Completed | K21: Chennai
A22: ORD-00021 | B22: 45470 | C22: CUST-0159 | D22: PROD-019 | E22: R006 | F22: 7 | G22: 2480 | H22: 28.7 | I22: 12377.68 | J22: Completed | K22: Hyderabad
A23: ORD-00022 | B23: 45354 | C23: CUST-0259 | D23: PROD-036 | E23: R030 | F23: 4 | G23: 3250 | H23: 24.6 | I23: 9802 | J23: Completed | K23: Mumbai | O23: Row Labels | P23: Sum of final_amount
A24: ORD-00023 | B24: 45530 | C24: CUST-0107 | D24: PROD-015 | E24: R030 | F24: 9 | G24: 2720 | H24: 26.2 | I24: 18066.24 | J24: Completed | K24: Pune | O24: (blank) | P24: 2440893.4
A25: ORD-00024 | B25: 45472 | C25: CUST-0101 | D25: PROD-044 | E25: R003 | F25: 2 | G25: 1650 | H25: 9.4 | I25: 2989.8 | J25: Completed | K25: Hyderabad | O25: (blank) | P25: 2440893.4
A26: ORD-00025 | B26: 45394 | C26: CUST-0142 | D26: PROD-043 | E26: R023 | F26: 6 | G26: 3350 | H26: 6.1 | I26: 18873.9 | J26: Pending | K26: Chennai | O26: (blank) | P26: 2440893.4
A27: ORD-00026 | B27: 45570 | C27: CUST-0250 | D27: PROD-054 | E27: R019 | F27: 2 | G27: 1010 | H27: 16.5 | I27: 1686.7 | J27: Cancelled | K27: Delhi | O27: North | P27: 31386.82
A28: ORD-00027 | B28: 45401 | C28: CUST-0098 | D28: PROD-046 | E28: R006 | F28: 5 | G28: 4880 | H28: 23.6 | I28: 18641.6 | J28: Completed | K28: Delhi | O28: Apparel | P28: 28301.44
A29: ORD-00028 | B29: 45517 | C29: CUST-0143 | D29: PROD-003 | E29: R015 | F29: 7 | G29: 3570 | H29: 5.8 | I29: 23540.58 | J29: Cancelled | K29: Chennai | O29: (blank) | P29: 28301.44
A30: ORD-00029 | B30: 45363 | C30: CUST-0086 | D30: PROD-048 | E30: R020 | F30: 9 | G30: 5100 | H30: 16.7 | I30: 38234.7 | J30: Completed | K30: Hyderabad | O30: Grocery | P30: 3085.38
A31: ORD-00030 | B31: 45367 | C31: CUST-0006 | D31: PROD-055 | E31: R005 | F31: 3 | G31: 2860 | H31: 25.8 | I31: 6366.36 | J31: Completed | K31: Pune | O31: (blank) | P31: 3085.38
A32: ORD-00031 | B32: 45569 | C32: CUST-0241 | D32: PROD-030 | E32: R006 | F32: 7 | G32: 970 | H32: 29.8 | I32: 4766.58 | J32: Completed | K32: Pune | O32: South | P32: 3635.92
A33: ORD-00032 | B33: 45641 | C33: CUST-0035 | D33: PROD-021 | E33: R026 | F33: 4 | G33: 2760 | H33: 5.9 | I33: 10388.64 | J33: Completed | K33: Hyderabad | O33: Sports | P33: 3635.92
A34: ORD-00033 | B34: 45343 | C34: CUST-0273 | D34: PROD-037 | E34: R009 | F34: 10 | G34: 660 | H34: 18.3 | I34: 5392.2 | J34: Pending | K34: Hyderabad | O34: (blank) | P34: 3635.92
A35: ORD-00034 | B35: 45576 | C35: CUST-0064 | D35: PROD-036 | E35: R019 | F35: 1 | G35: 3250 | H35: 10.7 | I35: 2902.25 | J35: Completed | K35: Hyderabad | O35: West | P35: 3763.76
... A43: ORD-00042 | B43: 45432 | C43: CUST-0053 | D43: PROD-046 | E43: R014 | F43: 10 | G43: 4880 | H43: 12.7 | I43: 42602.4 | J43: Completed | K43: Delhi | O43: Grand Total | P43: 2490845.3
A44: ORD-00043 | B44: 45392 | C44: CUST-0222 | D44: PROD-031 | E44: R019 | F44: 2 | G44: 3730 | H44: 25.8 | I44: 5535.32 | J44: Completed | K44: Chennai
A45: ORD-00044 | B45: 45396 | C45: CUST-0095 | D45: PROD-047 | E45: R029 | F45: 4 | G45: 3450 | H45: 20.7 | I45: 10943.4 | J45: Completed | K45: Mumbai
A46: ORD-00045 | B46: 45373 | C46: CUST-0152 | D46: PROD-019 | E46: R019 | F46: 2 | G46: 2480 | H46: 17.3 | I46: 4101.92 | J46: Completed | K46: Bengaluru
A47: ORD-00046 | B47: 45312 | C47: CUST-0291 | D47: PROD-027 | E47: R015 | F47: 9 | G47: 3780 | H47: 8.7 | I47: 31060.26 | J47: Pending | K47: Pune
...

Sheet Customers
A1: customer_id | B1: customer_name | C1: age | D1: city | E1: segment | F1: signup_date
A2: CUST-0001 | B2: Amit Agarwal | C2: 36 | D2: Pune | E2: Retail | F2: 44819
A3: CUST-0002 | B3: Vihaan Malhotra | C3: 42 | D3: Pune | E3: Corporate | F3: 44984
A4: CUST-0003 | B4: Navya Malhotra | C4: 33 | D4: Mumbai | E4: Retail | F4: 44059
A5: CUST-0004 | B5: Aaradhya Mehta | C5: 53 | D5: delhi | E5: Retail | F5: 44054
A6: CUST-0005 | B6: Myra Malhotra | C6: 52 | D6: Chennai | E6: Corporate | F6: 45037
A7: CUST-0006 | B7: Shaurya Iyer | C7: 44 | D7: Pune | E7: SMB | F7: 44302
A8: CUST-0007 | B8: Dhruv Joshi | C8: 47 | D8: Bengaluru | E8: Retail | F8: 44498
A9: CUST-0008 | B9: Kavita Malhotra | C9: 39 | D9: Pune | E9: SMB | F9: 45162
A10: CUST-0009 | B10: Neha Malhotra | C10: 61 | D10: Mumbai | E10: Retail | F10: 44343
A11: CUST-0010 | B11: Aaradhya Gupta | C11: 61 | D11: Mumbai | E11: SMB | F11: 44975
A12: CUST-0011 | B12: Diya Menon | C12: 41 | D12: Chennai | E12: Corporate | F12: 44821
A13: CUST-0012 | B13: Prisha Desai | C13: 43 | D13: Pune | E13: Retail | F13: 44718
... A301: CUST-0300 | B301: Rohit Nair | C301: 38 | D301: Mumbai | E301: Retail | F301: 43932

Sheet Products
A1: product_id | B1: product_name | C1: category | D1: unit_cost | E1: unit_price | F1: is_active
A2: PROD-001 | B2: Smartphone Pro | C2: Electronics | D2: 2405 | E2: 5330 | F2: TRUE
A3: PROD-002 | B3: Wireless Earbuds | C3: Electronics | D3: 1052 | E3: 2600 | F3: TRUE
A4: PROD-003 | B4: Smart Watch | C4: Electronics | D4: 1665 | E4: 3570 | F4: TRUE
A5: PROD-004 | B5: Laptop Bag | C5: Electronics | D5: 1559 | E5: 3870 | F5: TRUE
A6: PROD-005 | B6: Power Bank | C6: Electronics | D6: 128 | E6: 300 | F6: TRUE
A7: PROD-006 | B7: Bluetooth Speaker | C7: Electronics | D7: 2865 | E7: 3970 | F7: TRUE
A8: PROD-007 | B8: USB-C Cable | C8: Electronics | D8: 861 | E8: 1430 | F8: TRUE
A9: PROD-008 | B9: Wireless Mouse | C9: Electronics | D9: 1259 | E9: 2660 | F9: FALSE
A10: PROD-009 | B10: Mechanical Keyboard | C10: Electronics | D10: 517 | E10: 1220 | F10: TRUE
A11: PROD-010 | B11: Tablet Stand | C11: Electronics | D11: 1149 | E11: 2640 | F11: TRUE
A12: PROD-011 | B12: Cotton T-Shirt | C12: Apparel | D12: 1748 | E12: 3450 | F12: TRUE
A13: PROD-012 | B13: Denim Jeans | C13: Apparel | D13: 1886 | E13: 3160 | F13: TRUE
... A61: PROD-060 | B61: Gym Gloves | C61: Sports | D61: 147 | E61: 190 | F61: TRUE

Sheet Sales_Reps
A1: rep_id | B1: rep_name | C1: region | D1: hire_date | E1: team_lead_id
A2: R001 | B2: Rajesh Malhotra | C2: North | D2: 44207
A3: R002 | B3: Sunita Malhotra | C3: North | D3: 44028
A4: R003 | B4: Amit Singh | C4: North | D4: 43651
A5: R004 | B5: Priya Singh | C5: North | D5: 44907
A6: R005 | B6: Vikram Patel | C6: North | D6: 43588 | E6: R001
A7: R006 | B7: Neha Desai | C7: North | D7: 44131 | E7: R001
A8: R007 | B8: Suresh Menon | C8: North | D8: 43493 | E8: R001
A9: R008 | B9: Kavita Patel | C9: North | D9: 44693 | E9: R001
A10: R009 | B10: Manoj Patel | C10: South | D10: 44804 | E10: R002
A11: R010 | B11: Divya Rao | C11: South | D11: 43904 | E11: R002
A12: R011 | B12: Anil Verma | C12: South | D12: 44622 | E12: R002
A13: R012 | B13: Pooja Nair | C13: South | D13: 44890 | E13: R002
A14: R013 | B14: Sanjay Kapoor | C14: South | D14: 45215 | E14: R002
A15: R014 | B15: Ritu Menon | C15: South | D15: 44469 | E15: R002
A16: R015 | B16: Deepak Shah | C16: South | D16: 45231 | E16: R002
A17: R016 | B17: Anjali Chopra | C17: South | D17: 43614 | E17: R002
... A31: R030 | B31: Kiran Bhatt | C31: West | D31: 44506 | E31: R004

Sheet Targets
A1: rep_id | B1: Jan-24 | C1: Feb-24 | D1: Mar-24 | E1: Apr-24 | F1: May-24 | G1: Jun-24 | H1: Jul-24 | I1: Aug-24 | J1: Sep-24 | K1: Oct-24 | L1: Nov-24 | M1: Dec-24
A2: R001 | B2: 231324 | C2: 171682 | D2: 234376 | E2: 326967 | F2: 350588 | G2: 385324 | H2: 307980 | I2: 327947 | J2: 181016 | K2: 374039 | L2: 212805 | M2: 405999
A3: R002 | B3: 438126 | C3: 346266 | D3: 329993 | E3: 370744 | F3: 294660 | G3: 341556 | H3: 151934 | I3: 223794 | J3: 438641 | K3: 344308 | L3: 296172 | M3: 304288
A4: R003 | B4: 358703 | C4: 320519 | D4: 327321 | E4: 298753 | F4: 254636 | G4: 351929 | H4: 264723 | I4: 216459 | J4: 391945 | K4: 362426 | L4: 289199 | M4: 301863
A5: R004 | B5: 389594 | C5: 376422 | D5: 324156 | E5: 420255 | F5: 409107 | G5: 269954 | H5: 179097 | I5: 370568 | J5: 387395 | K5: 243454 | L5: 232530 | M5: 201999
A6: R005 | B6: 436862 | C6: 391158 | D6: 340224 | E6: 170548 | F6: 229390 | G6: 349525 | H6: 154683 | I6: 320848 | J6: 354452 | K6: 377180 | L6: 342347 | M6: 183362
A7: R006 | B7: 348734 | C7: 358191 | D7: 250385 | E7: 219657 | F7: 249365 | G7: 435704 | H7: 260892 | I7: 250741 | J7: 358402 | K7: 379858 | L7: 213280 | M7: 224634
A8: R007 | B8: 280057 | C8: 330342 | D8: 336856 | E8: 227425 | F8: 233647 | G8: 307088 | H8: 370724 | I8: 440008 | J8: 406347 | K8: 217357 | L8: 299289 | M8: 214568
A9: R008 | B9: 252886 | C9: 206057 | D9: 318209 | E9: 411230 | F9: 448660 | G9: 171135 | H9: 305339 | I9: 432264 | J9: 294273 | K9: 371409 | L9: 284207 | M9: 437068
A10: R009 | B10: 268752 | C10: 393256 | D10: 310649 | E10: 246237 | F10: 271287 | G10: 314545 | H10: 406506 | I10: 334930 | J10: 348625 | K10: 408928 | L10: 243749 | M10: 418409
A11: R010 | B11: 384734 | C11: 156698 | D11: 283679 | E11: 276085 | F11: 409270 | G11: 285230 | H11: 304233 | I11: 178221 | J11: 284216 | K11: 287373 | L11: 229082 | M11: 298969
A12: R011 | B12: 186029 | C12: 151419 | D12: 253251 | E12: 379757 | F12: 204209 | G12: 179396 | H12: 378008 | I12: 182649 | J12: 267772 | K12: 350352 | L12: 358042 | M12: 359960
A13: R012 | B13: 352158 | C13: 251181 | D13: 321255 | E13: 300863 | F13: 241731 | G13: 393275 | H13: 313561 | I13: 283604 | J13: 429065 | K13: 194420 | L13: 254168 | M13: 389283
... A31: R030 | B31: 151584 | C31: 221679 | D31: 385157 | E31: 290386 | F31: 236041 | G31: 407985 | H31: 184446 | I31: 342894 | J31: 180344 | K31: 292917 | L31: 314858 | M31: 364057

Sheet Q1_Lookups
A1: Q1 - LOOKUP FUNCTIONS (25 marks total)
A2: VLOOKUP · INDEX-MATCH · Two-way lookup · Chain lookup · Approximate lookup · Self-join
A4: Q# | B4: Question | C4: Marks | D4: Hint | E4: Your Answer | F4: Format
A5: Q1.1 | B5: For order ORD-00234, what is the customer_id? | C5: 3 | D5: Simple VLOOKUP on Orders sheet. | E5: =INDEX(Orders!C:C,MATCH("ORD-00234",Orders!A:A,0)) -> CUST-0173 | F5: CUST-####
A6: Q1.2 | B6: For order ORD-00456, what is the product_name? (You will need to look up the product_id first, then find its name in Products.) | C6: 3 | D6: Two-step lookup, or nested VLOOKUP. | E6: =INDEX(Products!B:B,MATCH(INDEX(Orders!D:D,MATCH("ORD-00456",Orders!A:A,0)),Products!A:A,0)) -> Dumbbells 5kg | F6: Text
A7: Q1.3 | B7: For order ORD-00987, what is the rep_name of the sales rep? Note: the rep_name is in a column that appears to the LEFT of what you might look up first. | C7: 3 | D7: VLOOKUP has directional limits - INDEX/MATCH does not. | E7: =INDEX(Sales_Reps!B:B,MATCH(INDEX(Orders!E:E,MATCH("ORD-00987",Orders!A:A,0)),Sales_Reps!A:A,0)) -> Nisha Menon | F7: Text
A8: Q1.4 | B8: From the Targets sheet, what is the target value for rep R012 in the month Mar-24? | C8: 4 | D8: Two-way lookup: row = rep_id, column = month. | E8: =INDEX(Targets!$B$2:$M$31,MATCH("R012",Targets!$A$2:$A$31,0),MATCH("Mar-24",Targets!$B$1:$M$1,0)) -> 321255 | F8: Whole number
A9: Q1.5 | B9: For order ORD-01500, what is the CATEGORY of the product ordered? (Chain: order → product_id → category) | C9: 4 | D9: Multi-hop lookup across sheets. | E9: =INDEX(Products!C:C,MATCH(INDEX(Orders!D:D,MATCH("ORD-01500",Orders!A:A,0)),Products!A:A,0)) -> Electronics | F9: Text
A10: Q1.6 | B10: For order ORD-00789, which DISCOUNT SLAB does it fall in? Use the slab table below (rows 20-24). Slab breakpoints are the LOWER bound of each range. | C10: 3 | D10: Approximate-match VLOOKUP (sort ascending, TRUE / omit last arg). | E10: =VLOOKUP(INDEX(Orders!H:H,MATCH("ORD-00789",Orders!A:A,0)),$B$18:$C$21,2,TRUE) -> Bronze | F10: Text
A11: Q1.7 | B11: For order ORD-01234, in one cell produce the string: "<rep_name> (<sales_region>)" - e.g. "Amit Singh (South)". | C11: 3 | D11: Two lookups joined with & or CONCATENATE. | E11: =INDEX(Sales_Reps!B:B,MATCH(INDEX(Orders!E:E,MATCH("ORD-01234",Orders!A:A,0)),Sales_Reps!A:A,0))&" ("&INDEX(Sales_Reps!C:C,MATCH(INDEX(Orders!E:E,MATCH("ORD-01234",Orders!A:A,0)),Sales_Reps!A:A,0))&")" -> Sanjay Kapoor (South) | F11: Text
A12: Q1.8 | B12: What is the rep_name of the TEAM LEAD for rep R017? (The Sales_Reps sheet has team_lead_id - you need to self-join to find that person's name.) | C12: 2 | D12: Look up the team_lead_id, then look up THAT id's rep_name. | E12: =INDEX(Sales_Reps!B:B,MATCH(INDEX(Sales_Reps!E:E,MATCH("R017",Sales_Reps!A:A,0)),Sales_Reps!A:A,0)) -> Amit Singh | F12: Text
B15: DISCOUNT SLAB REFERENCE TABLE (use for Q1.6)
B17: Discount % (Lower) | C17: Slab
B18: 0 | C18: Bronze
B19: 5 | C19: Silver
B20: 15 | C20: Gold
B21: 25 | C21: Platinum

Sheet Q2_Cleaning
A1: Q2 - DATA CLEANING & QUALITY DIAGNOSTICS (20 marks total)
A2: Duplicates · Whitespace · Case Inconsistency · Referential Integrity · Discontinued SKUs · Anomaly Patterns
A4: Q# | B4: Question | C4: Marks | D4: Hint | E4: Your Answer | F4: Format
A5: Q2.1 | B5: How many DUPLICATE rows exist in the Orders sheet (i.e., how many order_id values appear more than once)? Count each duplicate as ONE (not the extras). | C5: 3 | D5: COUNTIF > 1, then count. Watch what you're counting - rows or IDs. | E5: {=SUMPRODUCT((COUNTIF(Orders!$A$2:$A$2001,Orders!$A$2:$A$2001)>1)/COUNTIF(Orders!$A$2:$A$2001,Orders!$A$2:$A$2001))} -> 20 | F5: Whole number
A6: Q2.2 | B6: How many customers in the Customers sheet have LEADING or TRAILING whitespace in their customer_name? | C6: 3 | D6: Compare LEN vs LEN(TRIM). Or use SUMPRODUCT with a boolean. | E6: {=SUMPRODUCT(--(LEN(Customers!B2:B301)<>LEN(TRIM(Customers!B2:B301))))} -> 15 | F6: Whole number
A7: Q2.3 | B7: The Customers sheet has some cities in inconsistent case (e.g., "mumbai", "MUMBAI", "Mumbai"). How many DISTINCT cities exist AFTER standardizing case? | C7: 3 | D7: Combine PROPER/UPPER with a de-dup count. SUMPRODUCT + 1/COUNTIF trick works. | E7: {=SUMPRODUCT(1/COUNTIF(Customers!D2:D301,Customers!D2:D301))} -> 6 | F7: Whole number
A8: Q2.4 | B8: How many orders reference a customer_id that DOES NOT EXIST in the Customers sheet? (Broken foreign key) | C8: 4 | D8: Use MATCH with ISNA/ISERROR, then count. | E8: {=SUMPRODUCT(--ISNA(MATCH(Orders!C2:C2001,Customers!A2:A301,0)))} -> 30 | F8: Whole number
A9: Q2.5 | B9: How many orders reference a product that is currently DISCONTINUED (is_active = FALSE in the Products sheet)? | C9: 3 | D9: VLOOKUP the is_active flag, then count where FALSE. | E9: {=SUMPRODUCT(--(INDEX(Products!F2:F61,MATCH(Orders!D2:D2001,Products!A2:A61,0))=FALSE))} -> 174 | F9: Whole number
A10: Q2.6 | B10: Find the "suspicious pattern": how many orders have payment_status = "Cancelled" AND a discount_pct > 20%? (This pattern often indicates promo abuse - a real-world diagnostic query.) | C10: 4 | D10: COUNTIFS with two criteria. | E10: =COUNTIFS(Orders!J2:J2001,"Cancelled",Orders!H2:H2001,">20") -> 58 | F10: Whole number

Sheet Q3_Aggregation
A1: Q3 - CONDITIONAL AGGREGATION (25 marks total)
A2: SUMIFS · COUNTIFS · AVERAGEIFS · Nested IF logic · Multi-sheet aggregation · Top-N logic
A4: Q# | B4: Question | C4: Marks | D4: Hint | E4: Your Answer | F4: Format
A5: Q3.1 | B5: What is the TOTAL REVENUE (sum of final_amount) for orders in Q3 2024 (Jul-Sep) where ship_city is Mumbai? | C5: 4 | D5: SUMIFS with 3 conditions: date >= start, date <= end, city = Mumbai. Beware case issues. | E5: =SUMIFS(Orders!I2:I2001,Orders!B2:B2001,">="&DATE(2024,7,1),Orders!B2:B2001,"<="&DATE(2024,9,30),Orders!K2:K2001,"Mumbai") -> 1217239 | F5: Currency
A6: Q3.2 | B6: How many orders have discount_pct > 15% AND payment_status = "Completed"? | C6: 3 | D6: COUNTIFS with two conditions. | E6: =COUNTIFS(Orders!H2:H2001,">15",Orders!J2:J2001,"Completed") -> 723 | F6: Whole number
A7: Q3.3 | B7: What is the AVERAGE final_amount for orders where the product CATEGORY is "Electronics" AND the customer SEGMENT is "Corporate"? Note: Both fields come from OTHER sheets - you'll need helper columns. | C7: 5 | D7: Helper columns in Orders: VLOOKUP category from Products, VLOOKUP segment from Customers. Then AVERAGEIFS. | E7: {=SUMPRODUCT(LARGE(SUMIF(Orders!E2:E2001,Sales_Reps!A2:A31,Orders!I2:I2001),{1,2,3}))} -> 3342678.5 | F7: Currency
A8: Q3.4 | B8: What is the COMBINED REVENUE of the TOP 3 reps by total revenue? (Sum of the 3 highest rep totals.) | C8: 4 | D8: Compute per-rep totals, then use SUMPRODUCT with LARGE, or sort and sum top 3. | E8: {=SUMPRODUCT(LARGE(SUMIF(Orders!E2:E2001,Sales_Reps!A2:A31,Orders!I2:I2001),{1,2,3}))} -> 3342678.5 | F8: Currency
A9: Q3.5 | B9: For rep R015 in Nov-24: compute the actual revenue and compare to the target (from Targets sheet). Report the PERFORMANCE TIER using: <80% → "Below", 80-120% → "On Track", >120% → "Exceeds". Return only the tier text. | C9: 5 | D9: Nested IF (or IFS): compute actual/target ratio, then classify. | E9: =IF(SUMIFS(Orders!I2:I2001,Orders!E2:E2001,"R015",Orders!B2:B2001,">="&DATE(2024,11,1),Orders!B2:B2001,"<="&DATE(2024,11,30))/INDEX(Targets!B2:M31,MATCH("R015",Targets!A2:A31,0),MATCH("Nov-24",Targets!B1:M1,0))<0.8,"Below",IF(SUMIFS(Orders!I2:I2001,Orders!E2:E2001,"R015",Orders!B2:B2001,">="&DATE(2024,11,1),Orders!B2:B2001,"<="&DATE(2024,11,30))/INDEX(Targets!B2:M31,MATCH("R015",Targets!A2:A31,0),MATCH("Nov-24",Targets!B1:M1,0))<=1.2,"On Track","Exceeds")) -> Below | F9: Text
A10: Q3.6 | B10: What is the TOTAL revenue from Corporate segment customers aged between 30 and 40 (both inclusive)? | C10: 4 | D10: Helper columns for age and segment. Then SUMIFS with numeric range. | E10: {=SUMPRODUCT(SUMIF(Orders!C2:C2001,Customers!A2:A301,Orders!I2:I2001)*(Customers!E2:E301="Corporate")*(Customers!C2:C301>=30)*(Customers!C2:C301<=40))} -> 982568.4 | F10: Currency

Sheet Q4_Pivot
A1: Q4 - PIVOT TABLES (20 marks total)
A2: 2D Pivots · Filters · % of Row Total · Date Grouping · Calculated Fields · Cross-Sheet Data
A4: Q# | B4: Question | C4: Marks | D4: Hint | E4: Your Answer | F4: Format
A5: Q4.1 | B5: Build a pivot with sales_region as rows and product category as columns, values = SUM of final_amount. What value appears at the intersection of "South" and "Electronics"? | C5: 4 | D5: You need to add category (from Products) and region (from Sales_Reps) as columns to Orders first. Insert PivotTable from combined data. | E5: {=SUMPRODUCT(Orders!$I$2:$I$2001*(COUNTIFS(Sales_Reps!$A$2:$A$31,Orders!$E$2:$E$2001,Sales_Reps!$C$2:$C$31,"South")>0)*(COUNTIFS(Products!$A$2:$A$61,Orders!$D$2:$D$2001,Products!$C$2:$C$61,"Electronics")>0))} -> 1314107.4 | F5: Currency
A6: Q4.2 | B6: Build a pivot: rows = order month (Jan-24 through Dec-24), columns = sales_rep_id, values = SUM of final_amount. What is the HIGHEST single value in the entire pivot? (One number.) | C6: 4 | D6: After building, use MAX() over the pivot data range, or scan visually. | E6: {=SUMPRODUCT(MAX(SUMIFS(Orders!$I$2:$I$2001,Orders!$E$2:$E$2001,Sales_Reps!$A$2:$A$31,Orders!$B$2:$B$2001,">="&DATE(2024,COLUMN($A$1:$L$1),1),Orders!$B$2:$B$2001,"<"&DATE(2024,COLUMN($A$1:$L$1)+1,1))))} -> 216421.52 | F6: Currency
A7: Q4.3 | B7: For the North sales_region only: what PERCENTAGE of total revenue comes from the Apparel category? Configure the pivot with Show Values As → % of Row Total. | C7: 4 | D7: Pivot: rows=region, cols=category, values=sum(final_amount), Show Values As = % of Row Total. | E7: {=SUMPRODUCT(Orders!$I$2:$I$2001*(COUNTIFS(Sales_Reps!$A$2:$A$31,Orders!$E$2:$E$2001,Sales_Reps!$C$2:$C$31,"North")>0)*(COUNTIFS(Products!$A$2:$A$61,Orders!$D$2:$D$2001,Products!$C$2:$C$61,"Apparel")>0))/SUMPRODUCT(Orders!$I$2:$I$2001*(COUNTIFS(Sales_Reps!$A$2:$A$31,Orders!$E$2:$E$2001,Sales_Reps!$C$2:$C$31,"North")>0))} -> 0.1402315 | F7: Percentage
A8: Q4.4 | B8: Group order dates by QUARTER in a pivot. What is the total revenue for Q4 2024 (Oct-Dec)? | C8: 4 | D8: PivotTable → Group By → Quarter. Or SUMIFS with date range. | E8: =SUMIFS(Orders!$I$2:$I$2001,Orders!$B$2:$B$2001,">="&DATE(2024,10,1),Orders!$B$2:$B$2001,"<="&DATE(2024,12,31)) -> 6459443 | F8: Currency
A9: Q4.5 | B9: Create a CALCULATED FIELD in the pivot: profit_margin = (unit_price - unit_cost) / unit_price. What is the AVERAGE profit_margin for orders shipped to Delhi? Give as a percentage. | C9: 4 | D9: Add unit_cost via VLOOKUP as helper column. Create pivot calculated field, filter to Delhi. | E9: {=SUMPRODUCT((TRIM(Orders!$K$2:$K$2001)="Delhi")*(Orders!$G$2:$G$2001-SUMIF(Products!$A$2:$A$61,Orders!$D$2:$D$2001,Products!$D$2:$D$61))/Orders!$G$2:$G$2001)/SUMPRODUCT(--(TRIM(Orders!$K$2:$K$2001)="Delhi"))} -> 0.44903865 | F9: Percentage

Sheet Q5_Advanced
A1: Q5 - ADVANCED (10 marks total)
A2: RANK · Running Totals · TEXTJOIN · LARGE + INDEX/MATCH · Multi-condition top-N
A4: Q# | B4: Question | C4: Marks | D4: Hint | E4: Your Answer | F4: Format
A5: Q5.1 | B5: Rank all sales reps by total revenue (highest = rank 1). Who (name) is at RANK #7? | C5: 2 | D5: Per-rep totals, then use RANK.EQ, or sort. Return the rep_name at position 7. | E5: {=INDEX(Sales_Reps!$B$2:$B$31,SUMPRODUCT((SUMIF(Orders!$E$2:$E$2001,Sales_Reps!$A$2:$A$31,Orders!$I$2:$I$2001)=LARGE(SUMIF(Orders!$E$2:$E$2001,Sales_Reps!$A$2:$A$31,Orders!$I$2:$I$2001),7))*(ROW(Sales_Reps!$A$2:$A$31)-1)))} -> Amit Singh | F5: Text
A6: Q5.2 | B6: What is the CUMULATIVE revenue from Jan 2024 through the end of Aug 2024? (Sum of final_amount where order_date <= 31-Aug-2024.) | C6: 2 | D6: SUMIFS with date <=. | E6: =SUMIFS(Orders!$I$2:$I$2001,Orders!$B$2:$B$2001,"<="&DATE(2024,8,31)) -> 18050690 | F6: Currency
A7: Q5.3 | B7: Among orders where the sales rep is in the WEST region: which product (by name) has the 2nd highest total revenue? | C7: 3 | D7: Helper: sales_region on orders. Filter/pivot to West, sum by product, rank, get #2, VLOOKUP product name. | E7: {=INDEX(Products!$B$2:$B$61,MATCH(LARGE(MMULT(TRANSPOSE(--(Sales_Reps!$C$2:$C$31="West")),SUMIFS(Orders!$I$2:$I$2001,Orders!$D$2:$D$2001,TRANSPOSE(Products!$A$2:$A$61),Orders!$E$2:$E$2001,Sales_Reps!$A$2:$A$31)),2),MMULT(TRANSPOSE(--(Sales_Reps!$C$2:$C$31="West")),SUMIFS(Orders!$I$2:$I$2001,Orders!$D$2:$D$2001,TRANSPOSE(Products!$A$2:$A$61),Orders!$E$2:$E$2001,Sales_Reps!$A$2:$A$31)),0))} -> Smart Watch | F7: Text
A8: Q5.4 | B8: Concatenate the names of the top 5 reps by revenue into a single cell, separated by " | " (space-pipe-space). | C8: 2 | D8: TEXTJOIN with delimiter " | ". Combine with LARGE to pull top 5. | E8: {=_xlfn.TEXTJOIN(" | ",TRUE,INDEX(Sales_Reps!$B$2:$B$31,MATCH(LARGE(SUMIF(Orders!$E$2:$E$2001,Sales_Reps!$A$2:$A$31,Orders!$I$2:$I$2001),{1,2,3,4,5}),SUMIF(Orders!$E$2:$E$2001,Sales_Reps!$A$2:$A$31,Orders!$I$2:$I$2001),0)))} -> Neha Desai | Shalini Patel | Deepak Shah | Nisha Menon | Arun Iyer | F8: Text
A9: Q5.5 | B9: What is the HIGHEST single order value (final_amount) where ship_city = "Bengaluru" AND the product's category = "Grocery"? | C9: 1 | D9: MAXIFS with a category helper column, or nested MAX(IF()). | E9: {=SUMPRODUCT(MAX(Orders!$I$2:$I$2001*(TRIM(Orders!$K$2:$K$2001)="Bengaluru")*(COUNTIFS(Products!$A$2:$A$61,Orders!$D$2:$D$2001,Products!$C$2:$C$61,"Grocery")>0)))} -> 22134 | F9: Currency
